Workbook

Sheet README
A1: NorthBridge Health Services Ltd | B1: Customer Service Ticket & SLA Optimisation System - Dataset
A3: Sheet | B3: Row Count
A4: PriorityLevels | B4: 4
A5: TicketCategories | B5: 5
A6: SLADefinitions | B6: 12
A7: Agents | B7: 120
A8: Clients | B8: 80
A9: Tickets | B9: 3500
A10: TicketAuditLog | B10: 17751
A11: EscalationLog | B11: 464
A13: Date Range (Tickets) | B13: 1 Jan 2023 – 31 Mar 2025
A14: Ticket Categories | B14: Appointment Change · Billing Issue · Insurance Query · Complaint · Document Request
A15: SLA Breach Rate (approx) | B15: 21.5%
A16: Escalation Records | B16: 464
A17: Audit Log Entries | B17: 17751

Sheet PriorityLevels
A1: PriorityID | B1: PriorityLabel | C1: Description
A2: 1 | B2: P1 Critical | C2: Immediate risk to patient safety, legal/regulatory breach, or complete service outage. Assign within 15 minutes.
A3: 2 | B3: P2 High | C3: Significant financial impact, complaint from client executive, or billing error >£500. Assign within 1 hour.
A4: 3 | B4: P3 Standard | C4: Routine service request with defined SLA. Standard queue. Most tickets fall here.
A5: 4 | B5: P4 Low | C5: Informational queries, minor updates, or requests with flexible timelines.

Sheet TicketCategories
A1: CategoryID | B1: CategoryName | C1: DefaultPriorityID | D1: RequiresSpecialist | E1: Description
A2: 1 | B2: Appointment Change | C2: 3 | D2: 0 | E2: Request to reschedule, cancel, or add a patient appointment. Includes urgent and routine bookings.
A3: 2 | B3: Billing Issue | C3: 2 | D3: 1 | E3: Disputes, queries, or corrections relating to invoices, charges, or payment records.
A4: 3 | B4: Insurance Query | C4: 2 | D4: 1 | E4: Queries about pre-authorisation, claim status, policy coverage, or insurer correspondence.
A5: 4 | B5: Complaint | C5: 2 | D5: 0 | E5: Formal or informal patient or client complaint requiring logging, investigation, and response.
A6: 5 | B6: Document Request | C6: 3 | D6: 0 | E6: Requests for medical records, letters, referrals, certificates, or administrative documents.

Sheet SLADefinitions
A1: SLAID | B1: ContractTier | C1: PriorityID | D1: FirstResponseHours | E1: ResolutionHours | F1: EscalationTriggerHours | G1: EffectiveFrom
A2: 1 | B2: Standard | C2: 1 | D2: 2 | E2: 8 | F2: 6 | G2: 2023-01-01
A3: 2 | B3: Standard | C3: 2 | D3: 4 | E3: 24 | F3: 20 | G3: 2023-01-01
A4: 3 | B4: Standard | C4: 3 | D4: 8 | E4: 72 | F4: 60 | G4: 2023-01-01
A5: 4 | B5: Standard | C5: 4 | D5: 24 | E5: 120 | F5: 100 | G5: 2023-01-01
A6: 5 | B6: Premium | C6: 1 | D6: 1 | E6: 4 | F6: 3 | G6: 2023-01-01
A7: 6 | B7: Premium | C7: 2 | D7: 2 | E7: 12 | F7: 10 | G7: 2023-01-01
A8: 7 | B8: Premium | C8: 3 | D8: 4 | E8: 48 | F8: 40 | G8: 2023-01-01
A9: 8 | B9: Premium | C9: 4 | D9: 12 | E9: 96 | F9: 80 | G9: 2023-01-01
A10: 9 | B10: Enterprise | C10: 1 | D10: 0.5 | E10: 2 | F10: 1.5 | G10: 2023-01-01
A11: 10 | B11: Enterprise | C11: 2 | D11: 1 | E11: 8 | F11: 6 | G11: 2023-01-01
A12: 11 | B12: Enterprise | C12: 3 | D12: 2 | E12: 24 | F12: 20 | G12: 2023-01-01
A13: 12 | B13: Enterprise | C13: 4 | D13: 8 | E13: 72 | F13: 60 | G13: 2023-01-01

Sheet Agents
A1: AgentID | B1: FullName | C1: TeamID | D1: Role | E1: Specialisms | F1: Hub | G1: DailyCapacity | H1: IsActive
A2: 1 | B2: Parveen Szymański | C2: 1 | D2: Senior Agent | E2: Document Request,Insurance Query,Appointment Change | F2: Manchester | G2: 16 | H2: 1
A3: 2 | B3: Kirsty Morrison | C3: 1 | D3: Team Lead | E3: Document Request,Insurance Query,Complaint | F3: Manchester | G3: 11 | H3: 1
A4: 3 | B4: Alexander Johnson | C4: 1 | D4: Senior Agent | E4: Appointment Change,Billing Issue | F4: Manchester | G4: 19 | H4: 1
A5: 4 | B5: Eleanor Patel | C5: 1 | D5: Agent | E5: Insurance Query,Complaint | F5: Manchester | G5: 19 | H5: 1
A6: 5 | B6: Aisha Szymański | C6: 1 | D6: Agent | E6: Insurance Query,Appointment Change,Document Request | F6: Manchester | G6: 21 | H6: 1
A7: 6 | B7: Morag Iqbal | C7: 1 | D7: Agent | E7: Complaint,Insurance Query | F7: Manchester | G7: 20 | H7: 1
A8: 7 | B8: Charlotte Okafor | C8: 1 | D8: Agent | E8: Appointment Change | F8: Manchester | G8: 18 | H8: 1
A9: 8 | B9: Niamh Nguyen | C9: 1 | D9: Agent | E9: Insurance Query,Billing Issue,Document Request | F9: Manchester | G9: 21 | H9: 1
A10: 9 | B10: Liam Szymański | C10: 1 | D10: Senior Agent | E10: Billing Issue,Insurance Query,Appointment Change | F10: Manchester | G10: 19 | H10: 1
A11: 10 | B11: Eleanor Iqbal | C11: 1 | D11: Agent | E11: Document Request,Complaint | F11: Manchester | G11: 27 | H11: 1
A12: 11 | B12: Amelia Clarke | C12: 1 | D12: Agent | E12: Complaint,Appointment Change,Document Request | F12: Manchester | G12: 20 | H12: 1
A13: 12 | B13: Chloe Fraser | C13: 1 | D13: Agent | E13: Document Request,Appointment Change | F13: Manchester | G13: 28 | H13: 1
... A121: 120 | B121: Emily Zieliński | C121: 8 | D121: Agent | E121: Complaint | F121: Edinburgh | G121: 23 | H121: 1

Sheet Clients
A1: ClientID | B1: ClientName | C1: ClientType | D1: ContractTier | E1: AccountManagerID | F1: Region | G1: ContractStartDate | H1: ContractEndDate | I1: SLACreditClause | J1: IsActive
A2: 1 | B2: Ashworth Medical Centre | C2: Private Hospital | D2: Premium | E2: 41 | F2: South East | G2: 2010-05-01 | H2: 2013-10-19 | I2: 0 | J2: 1
A3: 2 | B3: Unity Health Clinic | C3: Dental Group | D3: Enterprise | E3: 92 | F3: Midlands | G3: 2016-03-01 | H3: 2018-04-16 | I3: 0 | J3: 1
A4: 3 | B4: Junction Health Clinic | C4: Private Hospital | D4: Premium | E4: 76 | F4: Midlands | G4: 2014-08-01 | H4: 2017-03-27 | I4: 1 | J4: 1
A5: 4 | B5: Arcadia Health Group | C5: Mental Health Clinic | D5: Enterprise | E5: 59 | F5: Yorkshire | G5: 2023-11-01 | H5: 2028-08-12 | I5: 1 | J5: 1
A6: 5 | B6: Parkside Specialist Clinic | C6: Private Hospital | D6: Standard | E6: 102 | F6: Scotland | G6: 2014-09-01 | H6: 2016-05-11 | I6: 0 | J6: 1
A7: 6 | B7: Vanguard Specialist Services | C7: GP Practice | D7: Premium | E7: 61 | F7: North East | G7: 2023-11-01 | H7: 2026-11-30 | I7: 0 | J7: 0
A8: 7 | B8: Elmwood GP Practice | C8: Physiotherapy Centre | D8: Enterprise | E8: 60 | F8: North East | G8: 2019-04-01 | H8: 2023-11-17 | I8: 0 | J8: 1
A9: 8 | B9: Edgehill Private Hospital | C9: Private Hospital | D9: Standard | E9: 102 | F9: Scotland | G9: 2012-01-01 | H9: 2013-03-17 | I9: 0 | J9: 1
A10: 9 | B10: Queensbury GP Practice | C10: Specialist Clinic | D10: Standard | E10: 59 | F10: North East | G10: 2016-08-01 | H10: 2019-08-30 | I10: 0 | J10: 1
A11: 10 | B11: Vale Dental Practice | C11: Specialist Clinic | D11: Enterprise | E11: 119 | F11: Scotland | G11: 2021-12-01 | H11: 2023-10-13 | I11: 1 | J11: 1
A12: 11 | B12: Northbrook Dental Group | C12: Mental Health Clinic | D12: Premium | E12: 72 | F12: Midlands | G12: 2021-06-01 | H12: 2023-08-19 | I12: 1 | J12: 1
A13: 12 | B13: Zenith Private Hospital | C13: GP Practice | D13: Standard | E13: 32 | F13: South East | G13: 2018-11-01 | H13: 2021-11-04 | I13: 0 | J13: 1
... A81: 80 | B81: District Health Clinic | C81: Physiotherapy Centre | D81: Standard | E81: 86 | F81: Midlands | G81: 2016-12-01 | H81: 2020-05-19 | I81: 0 | J81: 1

Sheet SLA_BREACH_ANALYSIS
A1: TicketID | B1: TicketReference | C1: ClientID | D1: PatientRef | E1: CategoryID | F1: PriorityID | G1: Status | H1: AssignedAgentID | I1: CreatedAt | J1: FirstResponseAt | K1: ResolvedAt | L1: SLADueAt | M1: SLABreached | N1: Channel | O1: Description | P1: ResolutionNotes | Q1: Index | R1: SLABREACHCHECK
A2: 1 | B2: NB-2024-00001 | C2: 70 | D2: PT-81496 | E2: 5 | F2: 3 | G2: Closed | H2: 111 | I2: 45497.987 | J2: 45498.102 | K2: 45500.441 | L2: 45500.987 | M2: 0 | N2: Phone | O2: Request for discharge summary for patient PT-81496. | P2: Insurance medical report completed and submitted to insurer within agreed timeframe. | Q2: 0 | R2: OK
A3: 2 | B3: NB-2024-00002 | C3: 51 | D3: PT-99051 | E3: 2 | F3: 1 | G3: Closed | H3: 32 | I3: 45602.99 | J3: 45603.048 | K3: 45603.197 | L3: 45603.323 | M3: 0 | N3: Portal | O3: Query regarding invoice 28714 dated 09 Oct 2024. Client reports disputed amount of £192. | P3: Charge dispute investigated. Original amount validated as correct; breakdown sent to client. | Q3: 1 | R3: OK
A4: 3 | B4: NB-2024-00003 | C4: 53 | D4: PT-24869 | E4: 3 | F4: 3 | G4: Closed | H4: 57 | I4: 45505.235 | J4: 45505.415 | K4: 45506.608 | L4: 45508.235 | M4: 0 | N4: Portal | O4: Pre-authorisation request for outpatient consultation. Patient PT-24869. Insurer: Vitality. | P4: Pre-auth declined by insurer. Patient advised of self-pay options and appeal pathway. | Q4: 2 | R4: OK
A5: 4 | B5: NB-2024-00004 | C5: 11 | D5: PT-55537 | E5: 1 | F5: 2 | G5: Closed | H5: 22 | I5: 45629.557 | J5: 45629.616 | K5: 45630.314 | L5: 45630.057 | M5: 1 | N5: Form | O5: Patient PT-55537 requesting addition of appointment originally booked for 05 Dec 2024. | P5: Cancellation processed. New appointment booked for following week per patient request. | Q5: 3 | R5: OK
A6: 5 | B6: NB-2023-00005 | C6: 70 | D6: PT-50539 | E6: 3 | F6: 2 | G6: Resolved | H6: 52 | I6: 44968.164 | J6: 44968.269 | K6: 44968.518 | L6: 44969.164 | M6: 0 | N6: Phone | O6: Pre-authorisation request for surgical procedure. Patient PT-50539. Insurer: WPA. | P6: Pre-authorisation confirmed with insurer. Reference number provided to client. | Q6: 4 | R6: OK
A7: 6 | B7: NB-2023-00006 | C7: 79 | D7: PT-31581 | E7: 3 | F7: 3 | G7: Closed | H7: 104 | I7: 45210.003 | J7: 45210.186 | K7: 45210.796 | L7: 45212.003 | M7: 0 | N7: Form | O7: Pre-authorisation request for physiotherapy course. Patient PT-31581. Insurer: Bupa. | P7: Policy coverage query resolved. Benefit schedule sent to patient for reference. | Q7: 5 | R7: OK
A8: 7 | B8: NB-2023-00007 | C8: 23 | D8: PT-20646 | E8: 1 | F8: 3 | G8: Closed | H8: 107 | I8: 45193.284 | J8: 45193.426 | K8: 45194.972 | L8: 45195.284 | M8: 0 | N8: Phone | O8: Patient PT-20646 requesting reschedule of appointment originally booked for 05 Oct 2023. | P8: Recurring appointment series updated following consultant schedule change. | Q8: 6 | R8: OK
A9: 8 | B9: NB-2024-00008 | C9: 57 | D9: PT-50970 | E9: 2 | F9: 3 | G9: Resolved | H9: 57 | I9: 45389.381 | J9: 45389.479 | K9: 45390.745 | L9: 45391.381 | M9: 0 | N9: Email | O9: Query regarding invoice 55268 dated 25 Mar 2024. Client reports duplicate payment of £3165. | P9: Charge dispute investigated. Original amount validated as correct; breakdown sent to client. | Q9: 7 | R9: OK
A10: 9 | B10: NB-2024-00009 | C10: 8 | D10: PT-50988 | E10: 2 | F10: 2 | G10: Closed | H10: 46 | I10: 45378.162 | J10: 45378.599 | K10: 45380.565 | L10: 45379.162 | M10: 1 | N10: Portal | O10: Query regarding invoice 30885 dated 11 Mar 2024. Client reports disputed amount of £2092. | P10: Late payment fee waived as a goodwill gesture following system error. Account adjusted. | Q10: 8 | R10: OK
A11: 10 | B11: NB-2024-00010 | C11: 8 | D11: PT-27555 | E11: 1 | F11: 3 | G11: Closed | H11: 87 | I11: 45364.405 | J11: 45364.562 | K11: 45365.508 | L11: 45367.405 | M11: 0 | N11: Phone | O11: Patient PT-27555 requesting cancellation of appointment originally booked for 25 Mar 2024. | P11: Cancellation processed. New appointment booked for following week per patient request. | Q11: 9 | R11: OK
A12: 11 | B12: NB-2024-00011 | C12: 79 | D12: PT-57920 | E12: 1 | F12: 3 | G12: Resolved | H12: 104 | I12: 45361.864 | J12: 45362.149 | K12: 45362.891 | L12: 45363.864 | M12: 0 | N12: Portal | O12: Patient PT-57920 requesting reschedule of appointment originally booked for 14 Mar 2024. | P12: Urgent appointment arranged within 24 hours following GP referral. Patient notified. | Q12: 10 | R12: OK
A13: 12 | B13: NB-2023-00012 | C13: 72 | D13: PT-76494 | E13: 2 | F13: 3 | G13: Resolved | H13: 38 | I13: 45144.475 | J13: 45144.587 | K13: 45148.297 | L13: 45146.475 | M13: 1 | N13: Form | O13: Query regarding invoice 74205 dated 14 Jul 2023. Client reports missing credit of £1995. | P13: Late payment fee waived as a goodwill gesture following system error. Account adjusted. | Q13: 11 | R13: OK
... A18: 17 | B18: NB-2023-00017 | C18: 41 | D18: PT-32946 | E18: 3 | F18: 2 | G18: Closed | H18: 104 | I18: 45019.239 | J18: 45019.3 | K18: 45020.426 | L18: 45019.739 | M18: 1 | N18: Email | O18: Pre-authorisation request for surgical procedure. Patient PT-32946. Insurer: Aviva. | P18: Pre-authorisation confirmed with insurer. Reference number provided to client. | Q18: 16 | R18: OK
A19: 18 | B19: NB-2025-00018 | C19: 64 | D19: PT-76088 | E19: 5 | F19: 3 | G19: Open | H19: 75 | I19: 45741.833 | L19: 45743.833 | M19: 0 | N19: Form | O19: Request for discharge summary for patient PT-76088. | Q19: 17 | R19: OPEN_TICKET
A20: 19 | B20: NB-2023-00019 | C20: 43 | D20: PT-22502 | E20: 1 | F20: 3 | G20: Closed | H20: 22 | I20: 45227.399 | J20: 45227.492 | K20: 45228.503 | L20: 45229.399 | M20: 0 | N20: Phone | O20: Patient PT-22502 requesting reschedule of appointment originally booked for 31 Oct 2023. | P20: Urgent appointment arranged within 24 hours following GP referral. Patient notified. | Q20: 18 | R20: OK
A21: 20 | B21: NB-2023-00020 | C21: 34 | D21: PT-50760 | E21: 1 | F21: 3 | G21: Resolved | H21: 107 | I21: 45023.84 | J21: 45024.04 | K21: 45030.05 | L21: 45026.84 | M21: 1 | N21: Email | O21: Patient PT-50760 requesting addition of appointment originally booked for 09 Apr 2023. | P21: Cancellation processed. New appointment booked for following week per patient request. | Q21: 19 | R21: OK
A22: 21 | B22: NB-2023-00021 | C22: 66 | D22: PT-20237 | E22: 2 | F22: 3 | G22: Closed | H22: 107 | I22: 45266.624 | J22: 45266.815 | K22: 45268.11 | L22: 45268.624 | M22: 0 | N22: Email | O22: Query regarding invoice 18094 dated 09 Nov 2023. Client reports duplicate payment of £2395. | P22: Charge dispute investigated. Original amount validated as correct; breakdown sent to client. | Q22: 20 | R22: OK
A23: 22 | B23: NB-2024-00022 | C23: 72 | D23: PT-50392 | E23: 3 | F23: 3 | G23: Resolved | H23: 116 | I23: 45619.366 | J23: 45619.473 | K23: 45620.814 | L23: 45621.366 | M23: 0 | N23: Email | O23: Pre-authorisation request for diagnostic imaging. Patient PT-50392. Insurer: WPA. | P23: Policy coverage query resolved. Benefit schedule sent to patient for reference. | Q23: 21 | R23: OK
A24: 23 | B24: NB-2025-00023 | C24: 10 | D24: PT-59081 | E24: 2 | F24: 1 | G24: Resolved | H24: 9 | I24: 45660.67 | J24: 45660.684 | K24: 45660.746 | L24: 45660.753 | M24: 0 | N24: Email | O24: Query regarding invoice 59479 dated 21 Dec 2024. Client reports incorrect charge of £2846. | P24: Late payment fee waived as a goodwill gesture following system error. Account adjusted. | Q24: 22 | R24: OK
A25: 24 | B25: NB-2023-00024 | C25: 1 | D25: PT-30332 | E25: 1 | F25: 4 | G25: Closed | H25: 35 | I25: 44962.651 | J25: 44962.915 | K25: 44965.012 | L25: 44966.651 | M25: 0 | N25: Phone | O25: Patient PT-30332 requesting cancellation of appointment originally booked for 09 Feb 2023. | P25: Recurring appointment series updated following consultant schedule change. | Q25: 23 | R25: OK
A26: 25 | B26: NB-2024-00025 | C26: 8 | D26: PT-47914 | E26: 2 | F26: 3 | G26: Closed | H26: 105 | I26: 45307.515 | J26: 45307.765 | K26: 45308.679 | L26: 45310.515 | M26: 0 | N26: Email | O26: Query regarding invoice 85511 dated 05 Jan 2024. Client reports missing credit of £1020. | P26: Billing query resolved following confirmation from insurer. Payment processing initiated. | Q26: 24 | R26: OK
A27: 26 | B27: NB-2023-00026 | C27: 70 | D27: PT-59343 | E27: 3 | F27: 3 | G27: Closed | H27: 50 | I27: 45000.165 | J27: 45000.328 | K27: 45001.347 | L27: 45003.165 | M27: 0 | N27: Form | O27: Pre-authorisation request for physiotherapy course. Patient PT-59343. Insurer: Cigna. | P27: Pre-auth declined by insurer. Patient advised of self-pay options and appeal pathway. | Q27: 25 | R27: OK
A28: 27 | B28: NB-2024-00027 | C28: 35 | D28: PT-16755 | E28: 2 | F28: 2 | G28: Resolved | H28: 27 | I28: 45323.455 | J28: 45323.542 | K28: 45324.278 | L28: 45324.455 | M28: 0 | N28: Email | O28: Query regarding invoice 98299 dated 12 Jan 2024. Client reports incorrect charge of £348. | P28: Billing query resolved following confirmation from insurer. Payment processing initiated. | Q28: 26 | R28: OK
A29: 28 | B29: NB-2025-00028 | C29: 19 | D29: PT-71112 | E29: 1 | F29: 2 | G29: Closed | H29: 28 | I29: 45671.31 | J29: 45671.348 | K29: 45671.55 | L29: 45671.81 | M29: 0 | N29: Portal | O29: Patient PT-71112 requesting addition of appointment originally booked for 25 Jan 2025. | P29: Appointment moved from afternoon to morning slot. Patient and GP practice both confirmed. | Q29: 27 | R29: OK
A30: 29 | B30: NB-2023-00029 | C30: 32 | D30: PT-59786 | E30: 2 | F30: 3 | G30: Closed | H30: 8 | I30: 45154.016 | J30: 45154.199 | K30: 45155.54 | L30: 45157.016 | M30: 0 | N30: Email | O30: Query regarding invoice 42208 dated 31 Jul 2023. Client reports missing credit of £1104. | P30: Billing query resolved following confirmation from insurer. Payment processing initiated. | Q30: 28 | R30: OK
A31: 30 | B31: NB-2023-00030 | C31: 78 | D31: PT-92667 | E31: 3 | F31: 3 | G31: Closed | H31: 71 | I31: 45018.57 | J31: 45019.304 | K31: 45020.249 | L31: 45021.57 | M31: 0 | N31: Email | O31: Pre-authorisation request for surgical procedure. Patient PT-92667. Insurer: Vitality. | P31: Pre-auth declined by insurer. Patient advised of self-pay options and appeal pathway. | Q31: 29 | R31: OK
... A39: 38 | B39: NB-2024-00038 | C39: 48 | D39: PT-72784 | E39: 4 | F39: 2 | G39: Closed | H39: 109 | I39: 45596.272 | J39: 45596.352 | K39: 45597.01 | L39: 45597.272 | M39: 0 | N39: Portal | O39: Formal complaint submitted by GP practice regarding poor communication. Reference needed. | P39: Complaint resolved following discussion with client. Compensation of £452 agreed and authorised. | Q39: 37 | R39: OK
A40: 39 | B40: NB-2023-00039 | C40: 78 | D40: PT-48185 | E40: 1 | F40: 3 | G40: Escalated | H40: 108 | I40: 45206.84 | J40: 45207.128 | L40: 45209.84 | M40: 1 | N40: Portal | O40: Patient PT-48185 requesting addition of appointment originally booked for 09 Oct 2023. | Q40: 38 | R40: OPEN_TICKET
A41: 40 | B41: NB-2025-00040 | C41: 63 | D41: PT-57124 | E41: 2 | F41: 2 | G41: Closed | H41: 78 | I41: 45671.798 | J41: 45672.172 | K41: 45672.597 | L41: 45672.798 | M41: 0 | N41: Phone | O41: Query regarding invoice 80373 dated 25 Dec 2024. Client reports incorrect charge of £497. | P41: Late payment fee waived as a goodwill gesture following system error. Account adjusted. | Q41: 39 | R41: OK
A42: 41 | B42: NB-2023-00041 | C42: 61 | D42: PT-59036 | E42: 5 | F42: 3 | G42: Resolved | H42: 1 | I42: 45091.912 | J42: 45092.124 | K42: 45093.23 | L42: 45094.912 | M42: 0 | N42: Email | O42: Request for insurance medical report for patient PT-59036. | P42: Medical records compiled and securely transmitted to requesting party within 72 hours. | Q42: 40 | R42: OK
A43: 42 | B43: NB-2025-00042 | C43: 30 | D43: PT-69303 | E43: 1 | F43: 3 | G43: Open | H43: 79 | I43: 45736.857 | L43: 45738.857 | M43: 0 | N43: Email | O43: Patient PT-69303 requesting cancellation of appointment originally booked for 22 Mar 2025. | Q43: 41 | R43: OPEN_TICKET
A44: 43 | B44: NB-2024-00043 | C44: 24 | D44: PT-61849 | E44: 1 | F44: 2 | G44: Closed | H44: 96 | I44: 45441.508 | J44: 45441.564 | K44: 45441.865 | L44: 45442.008 | M44: 0 | N44: Phone | O44: Patient PT-61849 requesting reschedule of appointment originally booked for 10 Jun 2024. | P44: Cancellation processed. New appointment booked for following week per patient request. | Q44: 42 | R44: OK
A45: 44 | B45: NB-2023-00044 | C45: 10 | D45: PT-79168 | E45: 3 | F45: 3 | G45: Resolved | H45: 116 | I45: 45085.399 | J45: 45085.447 | K45: 45086.243 | L45: 45086.399 | M45: 0 | N45: Portal | O45: Pre-authorisation request for outpatient consultation. Patient PT-79168. Insurer: Vitality. | P45: Claim status updated to approved. Payment expected within 5–7 working days. | Q45: 43 | R45: OK
A46: 45 | B46: NB-2024-00045 | C46: 21 | D46: PT-85340 | E46: 5 | F46: 3 | G46: Resolved | H46: 13 | I46: 45413.85 | J46: 45413.915 | K46: 45415.201 | L46: 45415.85 | M46: 0 | N46: Email | O46: Request for GP referral letter for patient PT-85340. | P46: Fit-to-work certificate issued following confirmation from treating clinician. | Q46: 44 | R46: OK
A47: 46 | B47: NB-2023-00046 | C47: 69 | D47: PT-68176 | E47: 4 | F47: 4 | G47: Closed | H47: 34 | I47: 45139.432 | J47: 45140.029 | K47: 45142.242 | L47: 45144.432 | M47: 0 | N47: Portal | O47: Formal complaint submitted by patient regarding poor communication. Reference needed. | P47: Complaint closed following satisfactory resolution. Client confirmed acceptance of outcome. | Q47: 45 | R47: OK
A48: 47 | B48: NB-2025-00047 | C48: 70 | D48: PT-15453 | E48: 3 | F48: 3 | G48: In Progress | H48: 13 | I48: 45720.842 | J48: 45721.141 | L48: 45723.842 | M48: 0 | N48: Phone | O48: Pre-authorisation request for diagnostic imaging. Patient PT-15453. Insurer: Vitality. | Q48: 46 | R48: OPEN_TICKET
A49: 48 | B49: NB-2023-00048 | C49: 62 | D49: PT-66120 | E49: 1 | F49: 3 | G49: Resolved | H49: 116 | I49: 45109.686 | J49: 45109.745 | K49: 45111.621 | L49: 45110.686 | M49: 1 | N49: Portal | O49: Patient PT-66120 requesting reschedule of appointment originally booked for 12 Jul 2023. | P49: Recurring appointment series updated following consultant schedule change. | Q49: 47 | R49: OK
A50: 49 | B50: NB-2024-00049 | C50: 43 | D50: PT-46349 | E50: 1 | F50: 3 | G50: Closed | H50: 90 | I50: 45342.636 | J50: 45342.782 | K50: 45344.394 | L50: 45344.636 | M50: 0 | N50: Form | O50: Patient PT-46349 requesting addition of appointment originally booked for 23 Feb 2024. | P50: Recurring appointment series updated following consultant schedule change. | Q50: 48 | R50: OK
A51: 50 | B51: NB-2023-00050 | C51: 11 | D51: PT-10324 | E51: 3 | F51: 3 | G51: Resolved | H51: 54 | I51: 45071.951 | J51: 45072.228 | K51: 45075 | L51: 45073.951 | M51: 1 | N51: Phone | O51: Pre-authorisation request for specialist referral. Patient PT-10324. Insurer: Aviva. | P51: Insurer contacted; claim resubmitted with corrected diagnosis code. Outcome pending. | Q51: 49 | R51: OK
...

Sheet SLA BREACH ANALYSIS
B1: SLA Breach by Priority
K2: Ticket Volume by Status
B3: Column Labels | R3: SLA BREACH RATE BY AGENT
B4: 0 | D4: 1 | F4: Total Count of TicketID | G4: Total Count of TicketID2 | K4: Row Labels | L4: Count of TicketID | M4: Count of TicketID2
A5: Row Labels | B5: Count of TicketID | C5: Count of TicketID2 | D5: Count of TicketID | E5: Count of TicketID2 | K5: Closed | L5: 1984 | M5: 0.56685714 | P5: Row Labels | Q5: Count of TicketID | R5: Sum of SLABreached | S5: Average of SLABreached2 | T5: Agents
A6: 1 | B6: 184 | C6: 0.71317829 | D6: 74 | E6: 0.28682171 | F6: 258 | G6: 1 | K6: Escalated | L6: 57 | M6: 0.016285714 | P6: 80 | Q6: 3 | R6: 2 | S6: 0.66666667 | T6: =_xlfn.XLOOKUP(P6,Agents!A:A,Agents!B:B,"Not Found") -> Eleanor Nwosu
A7: 2 | B7: 665 | C7: 0.79831933 | D7: 168 | E7: 0.20168067 | F7: 833 | G7: 1 | K7: In Progress | L7: 52 | M7: 0.014857143 | P7: 74 | Q7: 7 | R7: 4 | S7: 0.57142857 | T7: =_xlfn.XLOOKUP(P7,Agents!A:A,Agents!B:B,"Not Found") -> Lily Murphy
A8: 3 | B8: 1555 | C8: 0.78495709 | D8: 426 | E8: 0.21504291 | F8: 1981 | G8: 1 | K8: Open | L8: 46 | M8: 0.013142857 | P8: 98 | Q8: 17 | R8: 8 | S8: 0.47058824 | T8: =_xlfn.XLOOKUP(P8,Agents!A:A,Agents!B:B,"Not Found") -> Catriona Kofi
A9: 4 | B9: 342 | C9: 0.79906542 | D9: 86 | E9: 0.20093458 | F9: 428 | G9: 1 | K9: Pending Client | L9: 44 | M9: 0.012571429 | P9: 97 | Q9: 7 | R9: 3 | S9: 0.42857143 | T9: =_xlfn.XLOOKUP(P9,Agents!A:A,Agents!B:B,"Not Found") -> Dev Iqbal
A10: Grand Total | B10: 2746 | C10: 0.78457143 | D10: 754 | E10: 0.21542857 | F10: 3500 | G10: 1 | K10: Resolved | L10: 1317 | M10: 0.37628571 | P10: 30 | Q10: 19 | R10: 8 | S10: 0.42105263 | T10: =_xlfn.XLOOKUP(P10,Agents!A:A,Agents!B:B,"Not Found") -> Maya Smith
K11: Grand Total | L11: 3500 | M11: 1 | P11: 67 | Q11: 5 | R11: 2 | S11: 0.4 | T11: =_xlfn.XLOOKUP(P11,Agents!A:A,Agents!B:B,"Not Found") -> Lily Chaudhry
P12: 73 | Q12: 41 | R12: 15 | S12: 0.36585366 | T12: =_xlfn.XLOOKUP(P12,Agents!A:A,Agents!B:B,"Not Found") -> Noah Taylor
B13: SLA Breach by Category | P13: 35 | Q13: 56 | R13: 19 | S13: 0.33928571 | T13: =_xlfn.XLOOKUP(P13,Agents!A:A,Agents!B:B,"Not Found") -> Samuel Malik
K14: Ticket Volume by Chanel | P14: 85 | Q14: 21 | R14: 7 | S14: 0.33333333 | T14: =_xlfn.XLOOKUP(P14,Agents!A:A,Agents!B:B,"Not Found") -> Morag Jones
B15: Column Labels | P15: 10 | Q15: 9 | R15: 3 | S15: 0.33333333 | T15: =_xlfn.XLOOKUP(P15,Agents!A:A,Agents!B:B,"Not Found") -> Eleanor Iqbal
B16: 0 | D16: 1 | F16: Total Count of TicketID | G16: Total Count of TicketID2 | K16: Row Labels | L16: Count of TicketID | M16: Count of TicketID2 | P16: 86 | Q16: 24 | R16: 8 | S16: 0.33333333 | T16: =_xlfn.XLOOKUP(P16,Agents!A:A,Agents!B:B,"Not Found") -> Ciarán Murphy
A17: Row Labels | B17: Count of TicketID | C17: Count of TicketID2 | D17: Count of TicketID | E17: Count of TicketID2 | K17: Email | L17: 1221 | M17: 0.34885714 | P17: 18 | Q17: 3 | R17: 1 | S17: 0.33333333 | T17: =_xlfn.XLOOKUP(P17,Agents!A:A,Agents!B:B,"Not Found") -> Alfie Szymański
A18: 1 | B18: 955 | C18: 0.79583333 | D18: 245 | E18: 0.20416667 | F18: 1200 | G18: 1 | K18: Form | L18: 397 | M18: 0.11342857 | P18: 13 | Q18: 46 | R18: 15 | S18: 0.32608696 | T18: =_xlfn.XLOOKUP(P18,Agents!A:A,Agents!B:B,"Not Found") -> Amelia Szymański
A19: 2 | B19: 693 | C19: 0.79381443 | D19: 180 | E19: 0.20618557 | F19: 873 | G19: 1 | K19: Phone | L19: 905 | M19: 0.25857143 | P19: 5 | Q19: 38 | R19: 12 | S19: 0.31578947 | T19: =_xlfn.XLOOKUP(P19,Agents!A:A,Agents!B:B,"Not Found") -> Aisha Szymański
A20: 3 | B20: 552 | C20: 0.78186969 | D20: 154 | E20: 0.21813031 | F20: 706 | G20: 1 | K20: Portal | L20: 977 | M20: 0.27914286 | P20: 8 | Q20: 32 | R20: 10 | S20: 0.3125 | T20: =_xlfn.XLOOKUP(P20,Agents!A:A,Agents!B:B,"Not Found") -> Niamh Nguyen
A21: 4 | B21: 232 | C21: 0.75816993 | D21: 74 | E21: 0.24183007 | F21: 306 | G21: 1 | K21: Grand Total | L21: 3500 | M21: 1 | P21: 94 | Q21: 13 | R21: 4 | S21: 0.30769231 | T21: =_xlfn.XLOOKUP(P21,Agents!A:A,Agents!B:B,"Not Found") -> Neha Murray
A22: 5 | B22: 314 | C22: 0.75662651 | D22: 101 | E22: 0.24337349 | F22: 415 | G22: 1 | P22: 65 | Q22: 13 | R22: 4 | S22: 0.30769231 | T22: =_xlfn.XLOOKUP(P22,Agents!A:A,Agents!B:B,"Not Found") -> Daniel O'Sullivan
A23: Grand Total | B23: 2746 | C23: 0.78457143 | D23: 754 | E23: 0.21542857 | F23: 3500 | G23: 1 | P23: 12 | Q23: 36 | R23: 11 | S23: 0.30555556 | T23: =_xlfn.XLOOKUP(P23,Agents!A:A,Agents!B:B,"Not Found") -> Chloe Fraser
L24: Top 10 Tickets by Agents | P24: 87 | Q24: 33 | R24: 10 | S24: 0.3030303 | T24: =_xlfn.XLOOKUP(P24,Agents!A:A,Agents!B:B,"Not Found") -> Olivia McCarthy
P25: 72 | Q25: 44 | R25: 13 | S25: 0.29545455 | T25: =_xlfn.XLOOKUP(P25,Agents!A:A,Agents!B:B,"Not Found") -> Patrick Williams
B26: SLA Breach by Chanel | K26: Row Labels | L26: Count of TicketID | M26: Count of TicketID2 | P26: 70 | Q26: 17 | R26: 5 | S26: 0.29411765 | T26: =_xlfn.XLOOKUP(P26,Agents!A:A,Agents!B:B,"Not Found") -> Bridget Woźniak
K27: 102 | L27: 71 | M27: 0.1169687 | N27: =_xlfn.XLOOKUP(K27,Agents!A:A,Agents!B:B,"Not Found") -> Ananya Byrne | P27: 76 | Q27: 45 | R27: 13 | S27: 0.28888889 | T27: =_xlfn.XLOOKUP(P27,Agents!A:A,Agents!B:B,"Not Found") -> Henry Anderson
B28: Column Labels | K28: 40 | L28: 65 | M28: 0.10708402 | N28: =_xlfn.XLOOKUP(K28,Agents!A:A,Agents!B:B,"Not Found") -> Isla Clarke | P28: 26 | Q28: 56 | R28: 16 | S28: 0.28571429 | T28: =_xlfn.XLOOKUP(P28,Agents!A:A,Agents!B:B,"Not Found") -> Lucy Anderson
B29: 0 | D29: 1 | F29: Total Count of TicketID | G29: Total Count of TicketID2 | K29: 32 | L29: 63 | M29: 0.10378913 | N29: =_xlfn.XLOOKUP(K29,Agents!A:A,Agents!B:B,"Not Found") -> Charlie Nowak | P29: 37 | Q29: 7 | R29: 2 | S29: 0.28571429 | T29: =_xlfn.XLOOKUP(P29,Agents!A:A,Agents!B:B,"Not Found") -> Kirsty Martin
A30: Row Labels | B30: Count of TicketID | C30: Count of TicketID2 | D30: Count of TicketID | E30: Count of TicketID2 | K30: 105 | L30: 62 | M30: 0.10214168 | N30: =_xlfn.XLOOKUP(K30,Agents!A:A,Agents!B:B,"Not Found") -> Declan Osei | P30: 25 | Q30: 32 | R30: 9 | S30: 0.28125 | T30: =_xlfn.XLOOKUP(P30,Agents!A:A,Agents!B:B,"Not Found") -> Arjun Bakare
A31: Email | B31: 975 | C31: 0.7985258 | D31: 246 | E31: 0.2014742 | F31: 1221 | G31: 1 | K31: 119 | L31: 62 | M31: 0.10214168 | N31: =_xlfn.XLOOKUP(K31,Agents!A:A,Agents!B:B,"Not Found") -> Ava Kowalczyk | P31: 84 | Q31: 18 | R31: 5 | S31: 0.27777778 | T31: =_xlfn.XLOOKUP(P31,Agents!A:A,Agents!B:B,"Not Found") -> Nadia Ross
A32: Form | B32: 308 | C32: 0.77581864 | D32: 89 | E32: 0.22418136 | F32: 397 | G32: 1 | K32: 78 | L32: 59 | M32: 0.097199341 | N32: =_xlfn.XLOOKUP(K32,Agents!A:A,Agents!B:B,"Not Found") -> Angus Davies | P32: 6 | Q32: 18 | R32: 5 | S32: 0.27777778 | T32: =_xlfn.XLOOKUP(P32,Agents!A:A,Agents!B:B,"Not Found") -> Morag Iqbal
A33: Phone | B33: 689 | C33: 0.76132597 | D33: 216 | E33: 0.23867403 | F33: 905 | G33: 1 | K33: 100 | L33: 57 | M33: 0.093904448 | N33: =_xlfn.XLOOKUP(K33,Agents!A:A,Agents!B:B,"Not Found") -> Seamus Iqbal | P33: 103 | Q33: 22 | R33: 6 | S33: 0.27272727 | T33: =_xlfn.XLOOKUP(P33,Agents!A:A,Agents!B:B,"Not Found") -> Sophia Davies
A34: Portal | B34: 774 | C34: 0.79222108 | D34: 203 | E34: 0.20777892 | F34: 977 | G34: 1 | K34: 15 | L34: 56 | M34: 0.092257002 | N34: =_xlfn.XLOOKUP(K34,Agents!A:A,Agents!B:B,"Not Found") -> Edward Kowalczyk | P34: 1 | Q34: 48 | R34: 13 | S34: 0.27083333 | T34: =_xlfn.XLOOKUP(P34,Agents!A:A,Agents!B:B,"Not Found") -> Parveen Szymański
A35: Grand Total | B35: 2746 | C35: 0.78457143 | D35: 754 | E35: 0.21542857 | F35: 3500 | G35: 1 | K35: 35 | L35: 56 | M35: 0.092257002 | N35: =_xlfn.XLOOKUP(K35,Agents!A:A,Agents!B:B,"Not Found") -> Samuel Malik | P35: 36 | Q35: 15 | R35: 4 | S35: 0.26666667 | T35: =_xlfn.XLOOKUP(P35,Agents!A:A,Agents!B:B,"Not Found") -> Ava Byrne
K36: 26 | L36: 56 | M36: 0.092257002 | N36: =_xlfn.XLOOKUP(K36,Agents!A:A,Agents!B:B,"Not Found") -> Lucy Anderson | P36: 88 | Q36: 15 | R36: 4 | S36: 0.26666667 | T36: =_xlfn.XLOOKUP(P36,Agents!A:A,Agents!B:B,"Not Found") -> Patrick Zieliński
K37: Grand Total | L37: 607 | M37: 1 | P37: 38 | Q37: 34 | R37: 9 | S37: 0.26470588 | T37: =_xlfn.XLOOKUP(P37,Agents!A:A,Agents!B:B,"Not Found") -> Alfie O'Brien
B38: SLA Breach by Status | P38: 117 | Q38: 46 | R38: 12 | S38: 0.26086957 | T38: =_xlfn.XLOOKUP(P38,Agents!A:A,Agents!B:B,"Not Found") -> Parveen Campbell
P39: 108 | Q39: 36 | R39: 9 | S39: 0.25 | T39: =_xlfn.XLOOKUP(P39,Agents!A:A,Agents!B:B,"Not Found") -> Charlotte Kelly
B40: Column Labels | P40: 2 | Q40: 24 | R40: 6 | S40: 0.25 | T40: =_xlfn.XLOOKUP(P40,Agents!A:A,Agents!B:B,"Not Found") -> Kirsty Morrison
...

Sheet Response and Resolution Analysi
A3: Average of Response Time (Hours)
A4: 5.0574455
A7: Row Labels | B7: Average of Response Time (Hours)
A8: 1 | B8: 1.1814527
A9: 2 | B9: 2.4838586
A10: 3 | B10: 4.6610541
A11: 4 | B11: 14.235535
A12: Grand Total | B12: 5.0574455
A16: Row Labels | B16: Average of Resolution Time
A17: 1 | B17: 5.2895412
A18: 2 | B18: 14.978493
A19: 3 | B19: 47.297673
A20: 4 | B20: 83.438616
A21: Grand Total | B21: 40.85616

Sheet Monthly Trends
B1: Year Ticket volume | I1: Year and Quarter SLA breach rate
A3: Count of TicketID | B3: Column Labels | H3: Column Labels
A4: Row Labels | B4: 0 | C4: 1 | D4: Grand Total | H4: 0 | J4: 1 | L4: Total Count of TicketID | M4: Total Count of TicketID2
A5: 2023 | B5: 1246 | C5: 343 | D5: 1589 | G5: Row Labels | H5: Count of TicketID | I5: Count of TicketID2 | J5: Count of TicketID | K5: Count of TicketID2
A6: Qtr1 | B6: 303 | C6: 85 | D6: 388 | G6: 2023 | H6: 1246 | I6: 0.78414097 | J6: 343 | K6: 0.21585903 | L6: 1589 | M6: 1
A7: Jan | B7: 104 | C7: 31 | D7: 135 | G7: Qtr1 | H7: 303 | I7: 0.78092784 | J7: 85 | K7: 0.21907216 | L7: 388 | M7: 1
A8: Feb | B8: 85 | C8: 28 | D8: 113 | G8: Jan | H8: 104 | I8: 0.77037037 | J8: 31 | K8: 0.22962963 | L8: 135 | M8: 1
A9: Mar | B9: 114 | C9: 26 | D9: 140 | G9: Feb | H9: 85 | I9: 0.75221239 | J9: 28 | K9: 0.24778761 | L9: 113 | M9: 1
A10: Qtr2 | B10: 311 | C10: 87 | D10: 398 | G10: Mar | H10: 114 | I10: 0.81428571 | J10: 26 | K10: 0.18571429 | L10: 140 | M10: 1
A11: Qtr3 | B11: 310 | C11: 80 | D11: 390 | G11: Qtr2 | H11: 311 | I11: 0.78140704 | J11: 87 | K11: 0.21859296 | L11: 398 | M11: 1
A12: Qtr4 | B12: 322 | C12: 91 | D12: 413 | G12: Qtr3 | H12: 310 | I12: 0.79487179 | J12: 80 | K12: 0.20512821 | L12: 390 | M12: 1
A13: 2024 | B13: 1198 | C13: 313 | D13: 1511 | G13: Qtr4 | H13: 322 | I13: 0.77966102 | J13: 91 | K13: 0.22033898 | L13: 413 | M13: 1
A14: Qtr1 | B14: 285 | C14: 76 | D14: 361 | G14: 2024 | H14: 1198 | I14: 0.79285242 | J14: 313 | K14: 0.20714758 | L14: 1511 | M14: 1
A15: Jan | B15: 95 | C15: 30 | D15: 125 | G15: 2025 | H15: 302 | I15: 0.755 | J15: 98 | K15: 0.245 | L15: 400 | M15: 1
A16: Feb | B16: 96 | C16: 20 | D16: 116 | G16: Grand Total | H16: 2746 | I16: 0.78457143 | J16: 754 | K16: 0.21542857 | L16: 3500 | M16: 1
A17: Mar | B17: 94 | C17: 26 | D17: 120
A18: Qtr2 | B18: 309 | C18: 81 | D18: 390
A19: Qtr3 | B19: 312 | C19: 83 | D19: 395
A20: Qtr4 | B20: 292 | C20: 73 | D20: 365
A21: 2025 | B21: 302 | C21: 98 | D21: 400
A22: Grand Total | B22: 2746 | C22: 754 | D22: 3500

Sheet Agent-Workload Analaysis
E1: Top 10 busiest Agents
A3: Row Labels | B3: Count of TicketID | C3: Full Name | D3: Role | E3: Hub | F3: Daily Capacity | G3: Tickets Assigned | H3: Workload Pressure %
A4: 102 | B4: 71 | C4: {=_xlfn.XLOOKUP(A4,Agents_1[[#All],[AgentID]],Agents_1[[#All],[FullName]],"Not found")} -> Ananya Byrne | D4: {=_xlfn.XLOOKUP(A4,Agents_1[[#All],[AgentID]],Agents_1[[#All],[Role]],"Not found")} -> Senior Agent | E4: {=_xlfn.XLOOKUP(A4,Agents_1[[#All],[AgentID]],Agents_1[[#All],[Hub]],"Not found")} -> Edinburgh | F4: =_xlfn.XLOOKUP(A4,Agents_1[AgentID],Agents_1[DailyCapacity],"Not found") -> 18 | G4: =B4/F4 -> 3.9444444 | H4: =B4/F4*100 -> 394.44444
A5: 40 | B5: 65 | C5: {=_xlfn.XLOOKUP(A5,Agents_1[[#All],[AgentID]],Agents_1[[#All],[FullName]],"Not found")} -> Isla Clarke | D5: {=_xlfn.XLOOKUP(A5,Agents_1[[#All],[AgentID]],Agents_1[[#All],[Role]],"Not found")} -> Team Lead | E5: {=_xlfn.XLOOKUP(A5,Agents_1[[#All],[AgentID]],Agents_1[[#All],[Hub]],"Not found")} -> Manchester | F5: =_xlfn.XLOOKUP(A5,Agents_1[AgentID],Agents_1[DailyCapacity],"Not found") -> 14 | G5: =B5/F5 -> 4.6428571 | H5: =B5/F5*100 -> 464.28571
A6: 32 | B6: 63 | C6: {=_xlfn.XLOOKUP(A6,Agents_1[[#All],[AgentID]],Agents_1[[#All],[FullName]],"Not found")} -> Charlie Nowak | D6: {=_xlfn.XLOOKUP(A6,Agents_1[[#All],[AgentID]],Agents_1[[#All],[Role]],"Not found")} -> Team Lead | E6: {=_xlfn.XLOOKUP(A6,Agents_1[[#All],[AgentID]],Agents_1[[#All],[Hub]],"Not found")} -> Manchester | F6: =_xlfn.XLOOKUP(A6,Agents_1[AgentID],Agents_1[DailyCapacity],"Not found") -> 8 | G6: =B6/F6 -> 7.875 | H6: =B6/F6*100 -> 787.5
A7: 105 | B7: 62 | C7: {=_xlfn.XLOOKUP(A7,Agents_1[[#All],[AgentID]],Agents_1[[#All],[FullName]],"Not found")} -> Declan Osei | D7: {=_xlfn.XLOOKUP(A7,Agents_1[[#All],[AgentID]],Agents_1[[#All],[Role]],"Not found")} -> Team Lead | E7: {=_xlfn.XLOOKUP(A7,Agents_1[[#All],[AgentID]],Agents_1[[#All],[Hub]],"Not found")} -> Edinburgh | F7: =_xlfn.XLOOKUP(A7,Agents_1[AgentID],Agents_1[DailyCapacity],"Not found") -> 13 | G7: =B7/F7 -> 4.7692308 | H7: =B7/F7*100 -> 476.92308
A8: 119 | B8: 62 | C8: {=_xlfn.XLOOKUP(A8,Agents_1[[#All],[AgentID]],Agents_1[[#All],[FullName]],"Not found")} -> Ava Kowalczyk | D8: {=_xlfn.XLOOKUP(A8,Agents_1[[#All],[AgentID]],Agents_1[[#All],[Role]],"Not found")} -> Team Lead | E8: {=_xlfn.XLOOKUP(A8,Agents_1[[#All],[AgentID]],Agents_1[[#All],[Hub]],"Not found")} -> Edinburgh | F8: =_xlfn.XLOOKUP(A8,Agents_1[AgentID],Agents_1[DailyCapacity],"Not found") -> 13 | G8: =B8/F8 -> 4.7692308 | H8: =B8/F8*100 -> 476.92308
A9: 78 | B9: 59 | C9: {=_xlfn.XLOOKUP(A9,Agents_1[[#All],[AgentID]],Agents_1[[#All],[FullName]],"Not found")} -> Angus Davies | D9: {=_xlfn.XLOOKUP(A9,Agents_1[[#All],[AgentID]],Agents_1[[#All],[Role]],"Not found")} -> Team Lead | E9: {=_xlfn.XLOOKUP(A9,Agents_1[[#All],[AgentID]],Agents_1[[#All],[Hub]],"Not found")} -> Birmingham | F9: =_xlfn.XLOOKUP(A9,Agents_1[AgentID],Agents_1[DailyCapacity],"Not found") -> 14 | G9: =B9/F9 -> 4.2142857 | H9: =B9/F9*100 -> 421.42857
A10: 100 | B10: 57 | C10: {=_xlfn.XLOOKUP(A10,Agents_1[[#All],[AgentID]],Agents_1[[#All],[FullName]],"Not found")} -> Seamus Iqbal | D10: {=_xlfn.XLOOKUP(A10,Agents_1[[#All],[AgentID]],Agents_1[[#All],[Role]],"Not found")} -> Agent | E10: {=_xlfn.XLOOKUP(A10,Agents_1[[#All],[AgentID]],Agents_1[[#All],[Hub]],"Not found")} -> Edinburgh | F10: =_xlfn.XLOOKUP(A10,Agents_1[AgentID],Agents_1[DailyCapacity],"Not found") -> 28 | G10: =B10/F10 -> 2.0357143 | H10: =B10/F10*100 -> 203.57143
A11: 15 | B11: 56 | C11: {=_xlfn.XLOOKUP(A11,Agents_1[[#All],[AgentID]],Agents_1[[#All],[FullName]],"Not found")} -> Edward Kowalczyk | D11: {=_xlfn.XLOOKUP(A11,Agents_1[[#All],[AgentID]],Agents_1[[#All],[Role]],"Not found")} -> Agent | E11: {=_xlfn.XLOOKUP(A11,Agents_1[[#All],[AgentID]],Agents_1[[#All],[Hub]],"Not found")} -> Manchester | F11: =_xlfn.XLOOKUP(A11,Agents_1[AgentID],Agents_1[DailyCapacity],"Not found") -> 22 | G11: =B11/F11 -> 2.5454545 | H11: =B11/F11*100 -> 254.54545
A12: 35 | B12: 56 | C12: {=_xlfn.XLOOKUP(A12,Agents_1[[#All],[AgentID]],Agents_1[[#All],[FullName]],"Not found")} -> Samuel Malik | D12: {=_xlfn.XLOOKUP(A12,Agents_1[[#All],[AgentID]],Agents_1[[#All],[Role]],"Not found")} -> Senior Agent | E12: {=_xlfn.XLOOKUP(A12,Agents_1[[#All],[AgentID]],Agents_1[[#All],[Hub]],"Not found")} -> Manchester | F12: =_xlfn.XLOOKUP(A12,Agents_1[AgentID],Agents_1[DailyCapacity],"Not found") -> 14 | G12: =B12/F12 -> 4 | H12: =B12/F12*100 -> 400
A13: 26 | B13: 56 | C13: {=_xlfn.XLOOKUP(A13,Agents_1[[#All],[AgentID]],Agents_1[[#All],[FullName]],"Not found")} -> Lucy Anderson | D13: {=_xlfn.XLOOKUP(A13,Agents_1[[#All],[AgentID]],Agents_1[[#All],[Role]],"Not found")} -> Agent | E13: {=_xlfn.XLOOKUP(A13,Agents_1[[#All],[AgentID]],Agents_1[[#All],[Hub]],"Not found")} -> Manchester | F13: =_xlfn.XLOOKUP(A13,Agents_1[AgentID],Agents_1[DailyCapacity],"Not found") -> 18 | G13: =B13/F13 -> 3.1111111 | H13: =B13/F13*100 -> 311.11111
A14: Grand Total | B14: 607
C15: SLA BREACHES
A17: Count of TicketID | B17: Column Labels | H17: Sorted- Lrgest to smallest
A18: Row Labels | B18: 0 | C18: 1 | D18: Grand Total | E18: SLA BREACH % | F18: Role | G18: Full Name
A19: 102 | B19: 57 | C19: 14 | D19: 71 | E19: =C19/D19 -> 0.1971831 | F19: {=_xlfn.XLOOKUP(A19,Agents_1[[#All],[AgentID]],Agents_1[[#All],[Role]],"Not found")} -> Senior Agent | G19: {=_xlfn.XLOOKUP(A19,Agents_1[[#All],[AgentID]],Agents_1[[#All],[FullName]],"Not found")} -> Ananya Byrne
A20: 40 | B20: 51 | C20: 14 | D20: 65 | E20: =C20/D20 -> 0.21538462 | F20: {=_xlfn.XLOOKUP(A20,Agents_1[[#All],[AgentID]],Agents_1[[#All],[Role]],"Not found")} -> Team Lead | G20: {=_xlfn.XLOOKUP(A20,Agents_1[[#All],[AgentID]],Agents_1[[#All],[FullName]],"Not found")} -> Isla Clarke
A21: 32 | B21: 50 | C21: 13 | D21: 63 | E21: =C21/D21 -> 0.20634921 | F21: {=_xlfn.XLOOKUP(A21,Agents_1[[#All],[AgentID]],Agents_1[[#All],[Role]],"Not found")} -> Team Lead | G21: {=_xlfn.XLOOKUP(A21,Agents_1[[#All],[AgentID]],Agents_1[[#All],[FullName]],"Not found")} -> Charlie Nowak
A22: 105 | B22: 47 | C22: 15 | D22: 62 | E22: =C22/D22 -> 0.24193548 | F22: {=_xlfn.XLOOKUP(A22,Agents_1[[#All],[AgentID]],Agents_1[[#All],[Role]],"Not found")} -> Team Lead | G22: {=_xlfn.XLOOKUP(A22,Agents_1[[#All],[AgentID]],Agents_1[[#All],[FullName]],"Not found")} -> Declan Osei
A23: 119 | B23: 55 | C23: 7 | D23: 62 | E23: =C23/D23 -> 0.11290323 | F23: {=_xlfn.XLOOKUP(A23,Agents_1[[#All],[AgentID]],Agents_1[[#All],[Role]],"Not found")} -> Team Lead | G23: {=_xlfn.XLOOKUP(A23,Agents_1[[#All],[AgentID]],Agents_1[[#All],[FullName]],"Not found")} -> Ava Kowalczyk
A24: 78 | B24: 46 | C24: 13 | D24: 59 | E24: =C24/D24 -> 0.22033898 | F24: {=_xlfn.XLOOKUP(A24,Agents_1[[#All],[AgentID]],Agents_1[[#All],[Role]],"Not found")} -> Team Lead | G24: {=_xlfn.XLOOKUP(A24,Agents_1[[#All],[AgentID]],Agents_1[[#All],[FullName]],"Not found")} -> Angus Davies
A25: 100 | B25: 45 | C25: 12 | D25: 57 | E25: =C25/D25 -> 0.21052632 | F25: {=_xlfn.XLOOKUP(A25,Agents_1[[#All],[AgentID]],Agents_1[[#All],[Role]],"Not found")} -> Agent | G25: {=_xlfn.XLOOKUP(A25,Agents_1[[#All],[AgentID]],Agents_1[[#All],[FullName]],"Not found")} -> Seamus Iqbal
A26: 15 | B26: 44 | C26: 12 | D26: 56 | E26: =C26/D26 -> 0.21428571 | F26: {=_xlfn.XLOOKUP(A26,Agents_1[[#All],[AgentID]],Agents_1[[#All],[Role]],"Not found")} -> Agent | G26: {=_xlfn.XLOOKUP(A26,Agents_1[[#All],[AgentID]],Agents_1[[#All],[FullName]],"Not found")} -> Edward Kowalczyk
A27: 35 | B27: 37 | C27: 19 | D27: 56 | E27: =C27/D27 -> 0.33928571 | F27: {=_xlfn.XLOOKUP(A27,Agents_1[[#All],[AgentID]],Agents_1[[#All],[Role]],"Not found")} -> Senior Agent | G27: {=_xlfn.XLOOKUP(A27,Agents_1[[#All],[AgentID]],Agents_1[[#All],[FullName]],"Not found")} -> Samuel Malik
A28: 26 | B28: 40 | C28: 16 | D28: 56 | E28: =C28/D28 -> 0.28571429 | F28: {=_xlfn.XLOOKUP(A28,Agents_1[[#All],[AgentID]],Agents_1[[#All],[Role]],"Not found")} -> Agent | G28: {=_xlfn.XLOOKUP(A28,Agents_1[[#All],[AgentID]],Agents_1[[#All],[FullName]],"Not found")} -> Lucy Anderson
A29: Grand Total | B29: 472 | C29: 135 | D29: 607

Sheet Workload by Hub
A3: Row Labels | B3: Count of TicketID | C3: Hub | D3: Hub | E3: Total Tickets | F3: Total Workload % | H3: Hub | I3: Total Tickets | J3: % of Total
A4: 1 | B4: 48 | C4: {=_xlfn.XLOOKUP(A4,Agents_1[[#All],[AgentID]],Agents_1[[#All],[Hub]],"Not found")} -> Manchester | D4: {=_xlfn.UNIQUE(C4:C123)} -> Manchester | E4: =SUMIF($C$4:$C$123,D4,$B$4:$B$123) -> 1346 | F4: =E4/SUM($E$4:$E$7) -> 0.38457143 | H4: {=_xlfn.SORTBY(D4:F7,E4:E7,-1)} -> Manchester | I4: 1346 | J4: 0.38457143 | K4: =I4/SUM($I$4:$I$7) -> 0.38457143
A5: 2 | B5: 24 | C5: {=_xlfn.XLOOKUP(A5,Agents_1[[#All],[AgentID]],Agents_1[[#All],[Hub]],"Not found")} -> Manchester | D5: Leeds | E5: =SUMIF($C$4:$C$123,D5,$B$4:$B$123) -> 601 | F5: =E5/SUM($E$4:$E$7) -> 0.17171429 | H5: Edinburgh | I5: 817 | J5: 0.23342857
A6: 3 | B6: 44 | C6: {=_xlfn.XLOOKUP(A6,Agents_1[[#All],[AgentID]],Agents_1[[#All],[Hub]],"Not found")} -> Manchester | D6: Birmingham | E6: =SUMIF($C$4:$C$123,D6,$B$4:$B$123) -> 736 | F6: =E6/SUM($E$4:$E$7) -> 0.21028571 | H6: Birmingham | I6: 736 | J6: 0.21028571
A7: 4 | B7: 22 | C7: {=_xlfn.XLOOKUP(A7,Agents_1[[#All],[AgentID]],Agents_1[[#All],[Hub]],"Not found")} -> Manchester | D7: Edinburgh | E7: =SUMIF($C$4:$C$123,D7,$B$4:$B$123) -> 817 | F7: =E7/SUM($E$4:$E$7) -> 0.23342857 | H7: Leeds | I7: 601 | J7: 0.17171429
A8: 5 | B8: 38 | C8: {=_xlfn.XLOOKUP(A8,Agents_1[[#All],[AgentID]],Agents_1[[#All],[Hub]],"Not found")} -> Manchester | D8: 0
A9: 6 | B9: 18 | C9: {=_xlfn.XLOOKUP(A9,Agents_1[[#All],[AgentID]],Agents_1[[#All],[Hub]],"Not found")} -> Manchester
A10: 7 | B10: 23 | C10: {=_xlfn.XLOOKUP(A10,Agents_1[[#All],[AgentID]],Agents_1[[#All],[Hub]],"Not found")} -> Manchester
A11: 8 | B11: 32 | C11: {=_xlfn.XLOOKUP(A11,Agents_1[[#All],[AgentID]],Agents_1[[#All],[Hub]],"Not found")} -> Manchester
A12: 9 | B12: 54 | C12: {=_xlfn.XLOOKUP(A12,Agents_1[[#All],[AgentID]],Agents_1[[#All],[Hub]],"Not found")} -> Manchester
A13: 10 | B13: 9 | C13: {=_xlfn.XLOOKUP(A13,Agents_1[[#All],[AgentID]],Agents_1[[#All],[Hub]],"Not found")} -> Manchester
A14: 11 | B14: 44 | C14: {=_xlfn.XLOOKUP(A14,Agents_1[[#All],[AgentID]],Agents_1[[#All],[Hub]],"Not found")} -> Manchester
A15: 12 | B15: 36 | C15: {=_xlfn.XLOOKUP(A15,Agents_1[[#All],[AgentID]],Agents_1[[#All],[Hub]],"Not found")} -> Manchester
A16: 13 | B16: 46 | C16: {=_xlfn.XLOOKUP(A16,Agents_1[[#All],[AgentID]],Agents_1[[#All],[Hub]],"Not found")} -> Manchester
A17: 14 | B17: 44 | C17: {=_xlfn.XLOOKUP(A17,Agents_1[[#All],[AgentID]],Agents_1[[#All],[Hub]],"Not found")} -> Manchester
A18: 15 | B18: 56 | C18: {=_xlfn.XLOOKUP(A18,Agents_1[[#All],[AgentID]],Agents_1[[#All],[Hub]],"Not found")} -> Manchester
A19: 16 | B19: 37 | C19: {=_xlfn.XLOOKUP(A19,Agents_1[[#All],[AgentID]],Agents_1[[#All],[Hub]],"Not found")} -> Manchester
A20: 17 | B20: 34 | C20: {=_xlfn.XLOOKUP(A20,Agents_1[[#All],[AgentID]],Agents_1[[#All],[Hub]],"Not found")} -> Manchester
... A117: 120 | B117: 6 | C117: {=_xlfn.XLOOKUP(A117,Agents_1[[#All],[AgentID]],Agents_1[[#All],[Hub]],"Not found")} -> Edinburgh
A118: Grand Total | B118: 3500

Sheet Ticket and SLA BREACHES v CLIEN
C1: TOP 20 CLIENTS AND TICKETS
J2: TICKET SLA BREACHES
A3: Row Labels | B3: Count of TicketID | C3: Client | D3: Region | H3: Column Labels | S3: TICKET SLA BREACH RATE BY CLIENT
A4: 44 | B4: 67 | C4: =_xlfn.XLOOKUP(A4,'Clients'!A:A,'Clients'!B:B,"Not found") -> Bridgeway Private Hospital | D4: =_xlfn.XLOOKUP(A4,'Clients'!A:A,'Clients'!F:F,"Not found") -> Yorkshire | H4: 0 | J4: 1 | L4: Total Count of TicketID | M4: Total Count of TicketID2
A5: 52 | B5: 62 | C5: =_xlfn.XLOOKUP(A5,'Clients'!A:A,'Clients'!B:B,"Not found") -> Central Specialist Services | D5: =_xlfn.XLOOKUP(A5,'Clients'!A:A,'Clients'!F:F,"Not found") -> Scotland | G5: Row Labels | H5: Count of TicketID | I5: Count of TicketID2 | J5: Count of TicketID | K5: Count of TicketID2 | N5: Client | O5: Region | S5: Breach % | T5: Client
A6: 51 | B6: 60 | C6: =_xlfn.XLOOKUP(A6,'Clients'!A:A,'Clients'!B:B,"Not found") -> County Medical Centre | D6: =_xlfn.XLOOKUP(A6,'Clients'!A:A,'Clients'!F:F,"Not found") -> Scotland | G6: 44 | H6: 49 | I6: 0.73134328 | J6: 18 | K6: 0.26865672 | L6: 67 | M6: 1 | N6: =_xlfn.XLOOKUP(G6,'Clients'!A:A,'Clients'!B:B,"Not found") -> Bridgeway Private Hospital | O6: =_xlfn.XLOOKUP(G6,'Clients'!A:A,'Clients'!F:F,"Not found") -> Yorkshire | S6: 0.33333333 | T6: Marshfield Health Associates
A7: 30 | B7: 60 | C7: =_xlfn.XLOOKUP(A7,'Clients'!A:A,'Clients'!B:B,"Not found") -> Daleview Specialist Clinic | D7: =_xlfn.XLOOKUP(A7,'Clients'!A:A,'Clients'!F:F,"Not found") -> South East | G7: 57 | H7: 40 | I7: 0.70175439 | J7: 17 | K7: 0.29824561 | L7: 57 | M7: 1 | N7: =_xlfn.XLOOKUP(G7,'Clients'!A:A,'Clients'!B:B,"Not found") -> Royal GP Practice | O7: =_xlfn.XLOOKUP(G7,'Clients'!A:A,'Clients'!F:F,"Not found") -> North West | S7: 0.32 | T7: Crown GP Practice
A8: 12 | B8: 59 | C8: =_xlfn.XLOOKUP(A8,'Clients'!A:A,'Clients'!B:B,"Not found") -> Zenith Private Hospital | D8: =_xlfn.XLOOKUP(A8,'Clients'!A:A,'Clients'!F:F,"Not found") -> South East | G8: 9 | H8: 40 | I8: 0.70175439 | J8: 17 | K8: 0.29824561 | L8: 57 | M8: 1 | N8: =_xlfn.XLOOKUP(G8,'Clients'!A:A,'Clients'!B:B,"Not found") -> Queensbury GP Practice | O8: =_xlfn.XLOOKUP(G8,'Clients'!A:A,'Clients'!F:F,"Not found") -> North East | S8: 0.30612245 | T8: Northbrook Dental Group
A9: 50 | B9: 59 | C9: =_xlfn.XLOOKUP(A9,'Clients'!A:A,'Clients'!B:B,"Not found") -> Ironbridge Physiotherapy | D9: =_xlfn.XLOOKUP(A9,'Clients'!A:A,'Clients'!F:F,"Not found") -> North West | G9: 52 | H9: 46 | I9: 0.74193548 | J9: 16 | K9: 0.25806452 | L9: 62 | M9: 1 | N9: =_xlfn.XLOOKUP(G9,'Clients'!A:A,'Clients'!B:B,"Not found") -> Central Specialist Services | O9: =_xlfn.XLOOKUP(G9,'Clients'!A:A,'Clients'!F:F,"Not found") -> Scotland | S9: 0.29824561 | T9: Royal GP Practice
A10: 36 | B10: 58 | C10: =_xlfn.XLOOKUP(A10,'Clients'!A:A,'Clients'!B:B,"Not found") -> Pennine Health Group | D10: =_xlfn.XLOOKUP(A10,'Clients'!A:A,'Clients'!F:F,"Not found") -> South East | G10: 12 | H10: 43 | I10: 0.72881356 | J10: 16 | K10: 0.27118644 | L10: 59 | M10: 1 | N10: =_xlfn.XLOOKUP(G10,'Clients'!A:A,'Clients'!B:B,"Not found") -> Zenith Private Hospital | O10: =_xlfn.XLOOKUP(G10,'Clients'!A:A,'Clients'!F:F,"Not found") -> South East | S10: 0.29824561 | T10: Queensbury GP Practice
A11: 28 | B11: 58 | C11: =_xlfn.XLOOKUP(A11,'Clients'!A:A,'Clients'!B:B,"Not found") -> Devonshire Medical Centre | D11: =_xlfn.XLOOKUP(A11,'Clients'!A:A,'Clients'!F:F,"Not found") -> Yorkshire | G11: 62 | H11: 34 | I11: 0.68 | J11: 16 | K11: 0.32 | L11: 50 | M11: 1 | N11: =_xlfn.XLOOKUP(G11,'Clients'!A:A,'Clients'!B:B,"Not found") -> Crown GP Practice | O11: =_xlfn.XLOOKUP(G11,'Clients'!A:A,'Clients'!F:F,"Not found") -> Scotland | S11: 0.2962963 | T11: Jubilee Health Services
A12: 78 | B12: 58 | C12: =_xlfn.XLOOKUP(A12,'Clients'!A:A,'Clients'!B:B,"Not found") -> County Health Clinic | D12: =_xlfn.XLOOKUP(A12,'Clients'!A:A,'Clients'!F:F,"Not found") -> Yorkshire | G12: 11 | H12: 34 | I12: 0.69387755 | J12: 15 | K12: 0.30612245 | L12: 49 | M12: 1 | N12: =_xlfn.XLOOKUP(G12,'Clients'!A:A,'Clients'!B:B,"Not found") -> Northbrook Dental Group | O12: =_xlfn.XLOOKUP(G12,'Clients'!A:A,'Clients'!F:F,"Not found") -> Midlands | S12: 0.28301887 | T12: Belmont Specialist Services
A13: 9 | B13: 57 | C13: =_xlfn.XLOOKUP(A13,'Clients'!A:A,'Clients'!B:B,"Not found") -> Queensbury GP Practice | D13: =_xlfn.XLOOKUP(A13,'Clients'!A:A,'Clients'!F:F,"Not found") -> North East | G13: 31 | H13: 38 | I13: 0.71698113 | J13: 15 | K13: 0.28301887 | L13: 53 | M13: 1 | N13: =_xlfn.XLOOKUP(G13,'Clients'!A:A,'Clients'!B:B,"Not found") -> Belmont Specialist Services | O13: =_xlfn.XLOOKUP(G13,'Clients'!A:A,'Clients'!F:F,"Not found") -> Yorkshire | S13: 0.2826087 | T13: Yardley Medical Centre
A14: 57 | B14: 57 | C14: =_xlfn.XLOOKUP(A14,'Clients'!A:A,'Clients'!B:B,"Not found") -> Royal GP Practice | D14: =_xlfn.XLOOKUP(A14,'Clients'!A:A,'Clients'!F:F,"Not found") -> North West | G14: 51 | H14: 45 | I14: 0.75 | J14: 15 | K14: 0.25 | L14: 60 | M14: 1 | N14: =_xlfn.XLOOKUP(G14,'Clients'!A:A,'Clients'!B:B,"Not found") -> County Medical Centre | O14: =_xlfn.XLOOKUP(G14,'Clients'!A:A,'Clients'!F:F,"Not found") -> Scotland | S14: 0.2826087 | T14: County Specialist Services
A15: 32 | B15: 56 | C15: =_xlfn.XLOOKUP(A15,'Clients'!A:A,'Clients'!B:B,"Not found") -> Oakfield Specialist Clinic | D15: =_xlfn.XLOOKUP(A15,'Clients'!A:A,'Clients'!F:F,"Not found") -> South East | G15: 34 | H15: 28 | I15: 0.66666667 | J15: 14 | K15: 0.33333333 | L15: 42 | M15: 1 | N15: =_xlfn.XLOOKUP(G15,'Clients'!A:A,'Clients'!B:B,"Not found") -> Marshfield Health Associates | O15: =_xlfn.XLOOKUP(G15,'Clients'!A:A,'Clients'!F:F,"Not found") -> North West | S15: 0.27118644 | T15: Zenith Private Hospital
A16: 26 | B16: 55 | C16: =_xlfn.XLOOKUP(A16,'Clients'!A:A,'Clients'!B:B,"Not found") -> Copperfield GP Practice | D16: =_xlfn.XLOOKUP(A16,'Clients'!A:A,'Clients'!F:F,"Not found") -> North West | G16: 8 | H16: 41 | I16: 0.74545455 | J16: 14 | K16: 0.25454545 | L16: 55 | M16: 1 | N16: =_xlfn.XLOOKUP(G16,'Clients'!A:A,'Clients'!B:B,"Not found") -> Edgehill Private Hospital | O16: =_xlfn.XLOOKUP(G16,'Clients'!A:A,'Clients'!F:F,"Not found") -> Scotland | S16: 0.27083333 | T16: District GP Practice
A17: 61 | B17: 55 | C17: =_xlfn.XLOOKUP(A17,'Clients'!A:A,'Clients'!B:B,"Not found") -> City Specialist Services | D17: =_xlfn.XLOOKUP(A17,'Clients'!A:A,'Clients'!F:F,"Not found") -> Midlands | G17: 36 | H17: 44 | I17: 0.75862069 | J17: 14 | K17: 0.24137931 | L17: 58 | M17: 1 | N17: =_xlfn.XLOOKUP(G17,'Clients'!A:A,'Clients'!B:B,"Not found") -> Pennine Health Group | O17: =_xlfn.XLOOKUP(G17,'Clients'!A:A,'Clients'!F:F,"Not found") -> South East | S17: 0.26865672 | T17: Bridgeway Private Hospital
... A26: 1 | B26: 52 | C26: =_xlfn.XLOOKUP(A26,'Clients'!A:A,'Clients'!B:B,"Not found") -> Ashworth Medical Centre | D26: =_xlfn.XLOOKUP(A26,'Clients'!A:A,'Clients'!F:F,"Not found") -> South East | G26: 63 | H26: 41 | I26: 0.77358491 | J26: 12 | K26: 0.22641509 | L26: 53 | M26: 1 | N26: =_xlfn.XLOOKUP(G26,'Clients'!A:A,'Clients'!B:B,"Not found") -> District Specialist Services | O26: =_xlfn.XLOOKUP(G26,'Clients'!A:A,'Clients'!F:F,"Not found") -> North East | S26: 0.25 | T26: Central Health Clinic
A27: Grand Total | B27: 1297 | G27: 28 | H27: 46 | I27: 0.79310345 | J27: 12 | K27: 0.20689655 | L27: 58 | M27: 1 | N27: =_xlfn.XLOOKUP(G27,'Clients'!A:A,'Clients'!B:B,"Not found") -> Devonshire Medical Centre | O27: =_xlfn.XLOOKUP(G27,'Clients'!A:A,'Clients'!F:F,"Not found") -> Yorkshire | S27: 0.25 | T27: City Specialist Services
G28: 14 | H28: 37 | I28: 0.75510204 | J28: 12 | K28: 0.24489796 | L28: 49 | M28: 1 | N28: =_xlfn.XLOOKUP(G28,'Clients'!A:A,'Clients'!B:B,"Not found") -> Orchard Medical Centre | O28: =_xlfn.XLOOKUP(G28,'Clients'!A:A,'Clients'!F:F,"Not found") -> Yorkshire | S28: 0.24528302 | T28: Central GP Practice
G29: 76 | H29: 34 | I29: 0.73913043 | J29: 12 | K29: 0.26086957 | L29: 46 | M29: 1 | N29: =_xlfn.XLOOKUP(G29,'Clients'!A:A,'Clients'!B:B,"Not found") -> Crown Health Clinic | O29: =_xlfn.XLOOKUP(G29,'Clients'!A:A,'Clients'!F:F,"Not found") -> Midlands | S29: 0.24489796 | T29: Orchard Medical Centre
G30: 60 | H30: 34 | I30: 0.75555556 | J30: 11 | K30: 0.24444444 | L30: 45 | M30: 1 | N30: =_xlfn.XLOOKUP(G30,'Clients'!A:A,'Clients'!B:B,"Not found") -> District Health Clinic | O30: =_xlfn.XLOOKUP(G30,'Clients'!A:A,'Clients'!F:F,"Not found") -> North East | S30: 0.24444444 | T30: District Health Clinic
G31: 37 | H31: 37 | I31: 0.77083333 | J31: 11 | K31: 0.22916667 | L31: 48 | M31: 1 | N31: =_xlfn.XLOOKUP(G31,'Clients'!A:A,'Clients'!B:B,"Not found") -> Riverside Mental Health Services | O31: =_xlfn.XLOOKUP(G31,'Clients'!A:A,'Clients'!F:F,"Not found") -> Yorkshire | S31: 0.24444444 | T31: CrestCare Dental Group
G32: 2 | H32: 40 | I32: 0.78431373 | J32: 11 | K32: 0.21568627 | L32: 51 | M32: 1 | N32: =_xlfn.XLOOKUP(G32,'Clients'!A:A,'Clients'!B:B,"Not found") -> Unity Health Clinic | O32: =_xlfn.XLOOKUP(G32,'Clients'!A:A,'Clients'!F:F,"Not found") -> Midlands | S32: 0.24137931 | T32: Pennine Health Group
G33: 21 | H33: 31 | I33: 0.73809524 | J33: 11 | K33: 0.26190476 | L33: 42 | M33: 1 | N33: =_xlfn.XLOOKUP(G33,'Clients'!A:A,'Clients'!B:B,"Not found") -> Greenacre Dental Centre | O33: =_xlfn.XLOOKUP(G33,'Clients'!A:A,'Clients'!F:F,"Not found") -> North West | S33: 0.23913043 | T33: Royal GP Practice
G34: 59 | H34: 35 | I34: 0.76086957 | J34: 11 | K34: 0.23913043 | L34: 46 | M34: 1 | N34: =_xlfn.XLOOKUP(G34,'Clients'!A:A,'Clients'!B:B,"Not found") -> Royal GP Practice | O34: =_xlfn.XLOOKUP(G34,'Clients'!A:A,'Clients'!F:F,"Not found") -> Midlands | S34: 0.23913043 | T34: District Health Clinic
G35: 19 | H35: 34 | I35: 0.75555556 | J35: 11 | K35: 0.24444444 | L35: 45 | M35: 1 | N35: =_xlfn.XLOOKUP(G35,'Clients'!A:A,'Clients'!B:B,"Not found") -> CrestCare Dental Group | O35: =_xlfn.XLOOKUP(G35,'Clients'!A:A,'Clients'!F:F,"Not found") -> South East | S35: 0.23809524 | T35: Southbank Medical Associates
G36: 50 | H36: 48 | I36: 0.81355932 | J36: 11 | K36: 0.18644068 | L36: 59 | M36: 1 | N36: =_xlfn.XLOOKUP(G36,'Clients'!A:A,'Clients'!B:B,"Not found") -> Ironbridge Physiotherapy | O36: =_xlfn.XLOOKUP(G36,'Clients'!A:A,'Clients'!F:F,"Not found") -> North West | S36: 0.23076923 | T36: Arcadia Health Group
G37: 80 | H37: 35 | I37: 0.76086957 | J37: 11 | K37: 0.23913043 | L37: 46 | M37: 1 | N37: =_xlfn.XLOOKUP(G37,'Clients'!A:A,'Clients'!B:B,"Not found") -> District Health Clinic | O37: =_xlfn.XLOOKUP(G37,'Clients'!A:A,'Clients'!F:F,"Not found") -> Midlands | S37: 0.22916667 | T37: Riverside Mental Health Services
G38: 72 | H38: 33 | I38: 0.75 | J38: 11 | K38: 0.25 | L38: 44 | M38: 1 | N38: =_xlfn.XLOOKUP(G38,'Clients'!A:A,'Clients'!B:B,"Not found") -> City Specialist Services | O38: =_xlfn.XLOOKUP(G38,'Clients'!A:A,'Clients'!F:F,"Not found") -> Midlands | S38: 0.22641509 | T38: District Specialist Services
G39: 32 | H39: 46 | I39: 0.82142857 | J39: 10 | K39: 0.17857143 | L39: 56 | M39: 1 | N39: =_xlfn.XLOOKUP(G39,'Clients'!A:A,'Clients'!B:B,"Not found") -> Oakfield Specialist Clinic | O39: =_xlfn.XLOOKUP(G39,'Clients'!A:A,'Clients'!F:F,"Not found") -> South East | S39: 0.225 | T39: Queensgate Health Services
... G77: 5 | H77: 37 | I77: 0.86046512 | J77: 6 | K77: 0.13953488 | L77: 43 | M77: 1 | N77: =_xlfn.XLOOKUP(G77,'Clients'!A:A,'Clients'!B:B,"Not found") -> Parkside Specialist Clinic | O77: =_xlfn.XLOOKUP(G77,'Clients'!A:A,'Clients'!F:F,"Not found") -> Scotland | S77: 0.12068966 | T77: County Health Clinic
G78: Grand Total | H78: 2746 | I78: 0.78457143 | J78: 754 | K78: 0.21542857 | L78: 3500 | M78: 1

Sheet Descriptive Statistics
A1: Statistic | B1: Response Time (Hours) | C1: Resolution Time (Hours)
A2: Mean | B2: =AVERAGE(Tickets_Clean[Response Time (Hours)]) -> 5.0574455 | C2: =AVERAGE(Tickets_Clean[Resolution Time (hours)]) -> 40.85616
A3: Median | B3: =MEDIAN(Tickets_Clean[Response Time (Hours)]) -> 3.1 | C3: =MEDIAN(Tickets_Clean[Resolution Time (hours)]) -> 30.4
A4: Minimum | B4: =MIN(Tickets_Clean[Response Time (Hours)]) -> 0.15 | C4: =MIN(Tickets_Clean[Resolution Time (hours)]) -> 0.63333333
A5: Maximum | B5: =MAX(Tickets_Clean[Response Time (Hours)]) -> 66.5 | C5: =MAX(Tickets_Clean[Resolution Time (hours)]) -> 290.13333
A6: Standard Deviation | B6: =_xlfn.STDEV.S(Tickets_Clean[Response Time (Hours)]) -> 6.4973886 | C6: =_xlfn.STDEV.S(Tickets_Clean[Resolution Time (hours)]) -> 38.614549
A7: 75th Percentile | B7: =_xlfn.PERCENTILE.INC(Tickets_Clean[Response Time (Hours)],0.75) -> 6 | C7: =_xlfn.PERCENTILE.INC(Tickets_Clean[Resolution Time (hours)],0.75) -> 53.666667
A8: 90th Percentile | B8: =_xlfn.PERCENTILE.INC(Tickets_Clean[Response Time (Hours)],0.9) -> 10.475 | C8: =_xlfn.PERCENTILE.INC(Tickets_Clean[Resolution Time (hours)],0.9) -> 91.733333

Sheet Tickets_Clean
A1: TicketID | B1: TicketReference | C1: ClientID | D1: PatientRef | E1: CategoryID | F1: PriorityID | G1: Status | H1: AssignedAgentID | I1: CreatedAt | J1: FirstResponseAt | K1: ResolvedAt | L1: SLADueAt | M1: SLABreached | N1: Channel | O1: Description | P1: ResolutionNotes | Q1: Index | R1: SLABREACHCHECK | S1: Response Time | T1: Resolution Time (hours) | U1: SLA_STATUS | V1: BREACHED TICKETS | W1: Response Time (Hours)
A2: 1 | B2: NB-2024-00001 | C2: 70 | D2: PT-81496 | E2: 5 | F2: 3 | G2: Closed | H2: 111 | I2: 45497.987 | J2: 45498.102 | K2: 45500.441 | L2: 45500.987 | M2: 0 | N2: Phone | O2: Request for discharge summary for patient PT-81496. | P2: Insurance medical report completed and submitted to insurer within agreed timeframe. | Q2: 0 | R2: OK | S2: 2.7666667 | T2: 58.9 | U2: Within SLA | V2: 0 | W2: 2.7666667
A3: 2 | B3: NB-2024-00002 | C3: 51 | D3: PT-99051 | E3: 2 | F3: 1 | G3: Closed | H3: 32 | I3: 45602.99 | J3: 45603.048 | K3: 45603.197 | L3: 45603.323 | M3: 0 | N3: Portal | O3: Query regarding invoice 28714 dated 09 Oct 2024. Client reports disputed amount of £192. | P3: Charge dispute investigated. Original amount validated as correct; breakdown sent to client. | Q3: 1 | R3: OK | S3: 1.4 | T3: 4.9833333 | U3: Within SLA | V3: 0 | W3: 1.4
A4: 3 | B4: NB-2024-00003 | C4: 53 | D4: PT-24869 | E4: 3 | F4: 3 | G4: Closed | H4: 57 | I4: 45505.235 | J4: 45505.415 | K4: 45506.608 | L4: 45508.235 | M4: 0 | N4: Portal | O4: Pre-authorisation request for outpatient consultation. Patient PT-24869. Insurer: Vitality. | P4: Pre-auth declined by insurer. Patient advised of self-pay options and appeal pathway. | Q4: 2 | R4: OK | S4: 4.3166667 | T4: 32.933333 | U4: Within SLA | V4: 0 | W4: 4.3166667
A5: 4 | B5: NB-2024-00004 | C5: 11 | D5: PT-55537 | E5: 1 | F5: 2 | G5: Closed | H5: 22 | I5: 45629.557 | J5: 45629.616 | K5: 45630.314 | L5: 45630.057 | M5: 1 | N5: Form | O5: Patient PT-55537 requesting addition of appointment originally booked for 05 Dec 2024. | P5: Cancellation processed. New appointment booked for following week per patient request. | Q5: 3 | R5: OK | S5: 1.4166667 | T5: 18.166667 | U5: Breached | V5: 1 | W5: 1.4166667
A6: 5 | B6: NB-2023-00005 | C6: 70 | D6: PT-50539 | E6: 3 | F6: 2 | G6: Resolved | H6: 52 | I6: 44968.164 | J6: 44968.269 | K6: 44968.518 | L6: 44969.164 | M6: 0 | N6: Phone | O6: Pre-authorisation request for surgical procedure. Patient PT-50539. Insurer: WPA. | P6: Pre-authorisation confirmed with insurer. Reference number provided to client. | Q6: 4 | R6: OK | S6: 2.5166667 | T6: 8.5 | U6: Within SLA | V6: 0 | W6: 2.5166667
